<?xml version="1.0"?>
<robot name="mecanum_robot">

  <!-- Link raiz: referência no chão -->
  <link name="base_footprint">
    <visual>
      <origin xyz="0 0 0" rpy="0 0 0"/>
      <geometry>
        <box size="0.00025 0.00025 0.00025"/>
      </geometry>
    </visual>
  </link>

  <!-- Junta fixa entre base_footprint e base_link -->
  <joint name="base_link_joint" type="fixed">
    <origin xyz="0 0 0.0125" rpy="0 0 0"/>
    <parent link="base_footprint"/>
    <child link="base_link"/>
  </joint>

  <!-- Base sólida do robô -->
  <link name="base_link">
    <inertial>
      <origin xyz="0 0 0.0125"/>
      <mass value="50.0"/>
      <inertia ixx="10.0" ixy="0" ixz="0" iyy="10.0" iyz="0" izz="10.0"/>
    </inertial>
    <visual>
      <origin xyz="0 0 0.0125"/>
      <geometry>
        <box size="0.15 0.15 0.025"/>
      </geometry>
      <material name="grey">
        <color rgba="0.6 0.6 0.6 1"/>
      </material>
    </visual>
    <collision>
      <origin xyz="0 0 0.0125"/>
      <geometry>
        <box size="0.15 0.15 0.025"/>
      </geometry>
    </collision>
  </link>
  
  <!-- Definição das rodas com rotação ajustada (90° adicionais) -->
  <!-- Roda dianteira esquerda -->
  <link name="wheel_front_left">
    <inertial>
      <origin xyz="0 0 0"/>
      <mass value="2.0"/>
      <inertia ixx="0.01" ixy="0" ixz="0" iyy="0.01" iyz="0" izz="0.01"/>
    </inertial>
    <visual>
      <!-- Rotaciona: primeiro 90° em torno de Y e depois 90° em torno de Z -->
      <origin xyz="0 0 0" rpy="0 1.57 1.57"/>
      <geometry>
        <cylinder length="0.0125" radius="0.025"/>
      </geometry>
      <material name="black">
        <color rgba="0 0 0 1"/>
      </material>
    </visual>
    <collision>
      <origin xyz="0 0 0" rpy="0 1.57 1.57"/>
      <geometry>
        <cylinder length="0.0125" radius="0.025"/>
      </geometry>
    </collision>
  </link>

  <!-- Roda dianteira direita -->
  <link name="wheel_front_right">
    <inertial>
      <origin xyz="0 0 0"/>
      <mass value="2.0"/>
      <inertia ixx="0.01" ixy="0" ixz="0" iyy="0.01" iyz="0" izz="0.01"/>
    </inertial>
    <visual>
      <origin xyz="0 0 0" rpy="0 1.57 1.57"/>
      <geometry>
        <cylinder length="0.0125" radius="0.025"/>
      </geometry>
      <material name="black">
        <color rgba="0 0 0 1"/>
      </material>
    </visual>
    <collision>
      <origin xyz="0 0 0" rpy="0 1.57 1.57"/>
      <geometry>
        <cylinder length="0.0125" radius="0.025"/>
      </geometry>
    </collision>
  </link>

  <!-- Roda traseira esquerda -->
  <link name="wheel_rear_left">
    <inertial>
      <origin xyz="0 0 0"/>
      <mass value="2.0"/>
      <inertia ixx="0.01" ixy="0" ixz="0" iyy="0.01" iyz="0" izz="0.01"/>
    </inertial>
    <visual>
      <origin xyz="0 0 0" rpy="0 1.57 1.57"/>
      <geometry>
        <cylinder length="0.0125" radius="0.025"/>
      </geometry>
      <material name="black">
        <color rgba="0 0 0 1"/>
      </material>
    </visual>
    <collision>
      <origin xyz="0 0 0" rpy="0 1.57 1.57"/>
      <geometry>
        <cylinder length="0.0125" radius="0.025"/>
      </geometry>
    </collision>
  </link>

  <!-- Roda traseira direita -->
  <link name="wheel_rear_right">
    <inertial>
      <origin xyz="0 0 0"/>
      <mass value="2.0"/>
      <inertia ixx="0.01" ixy="0" ixz="0" iyy="0.01" iyz="0" izz="0.01"/>
    </inertial>
    <visual>
      <origin xyz="0 0 0" rpy="0 1.57 1.57"/>
      <geometry>
        <cylinder length="0.0125" radius="0.025"/>
      </geometry>
      <material name="black">
        <color rgba="0 0 0 1"/>
      </material>
    </visual>
    <collision>
      <origin xyz="0 0 0" rpy="0 1.57 1.57"/>
      <geometry>
        <cylinder length="0.0125" radius="0.025"/>
      </geometry>
    </collision>
  </link>

  <!-- Juntas das rodas com eixo de rotação ajustado -->
  <joint name="joint_wheel_front_left" type="revolute">
    <origin xyz="0.075 0.075 0.0125" rpy="0 0 0"/>
    <parent link="base_link"/>
    <child link="wheel_front_left"/>
    <axis xyz="0 1 0"/>
    <limit effort="100" velocity="10"/>
  </joint>

  <joint name="joint_wheel_front_right" type="revolute">
    <origin xyz="0.075 -0.075 0.0125" rpy="0 0 0"/>
    <parent link="base_link"/>
    <child link="wheel_front_right"/>
    <axis xyz="0 1 0"/>
    <limit effort="100" velocity="10"/>
  </joint>

  <joint name="joint_wheel_rear_left" type="revolute">
    <origin xyz="-0.075 0.075 0.0125" rpy="0 0 0"/>
    <parent link="base_link"/>
    <child link="wheel_rear_left"/>
    <axis xyz="0 1 0"/>
    <limit effort="100" velocity="10"/>
  </joint>

  <joint name="joint_wheel_rear_right" type="revolute">
    <origin xyz="-0.075 -0.075 0.0125" rpy="0 0 0"/>
    <parent link="base_link"/>
    <child link="wheel_rear_right"/>
    <axis xyz="0 1 0"/>
    <limit effort="100" velocity="10"/>
  </joint>

  <!-- LIDAR colado na base -->
  <link name="laser">
    <material>Gazebo/FlatBlack</material>
    <inertial>
      <origin xyz="0 0 0"/>
      <mass value="1.0"/>
      <inertia ixx="0.001" ixy="0" ixz="0" iyy="0.001" iyz="0" izz="0.001"/>
    </inertial>
    <visual>
      <origin xyz="0 0 0" rpy="0 0 0"/>
      <geometry>
        <cylinder radius="0.0125" length="0.0125"/>
      </geometry>
      <material name="red">
        <color rgba="1 0 0 1"/>
      </material>
    </visual>
    <collision>
      <origin xyz="0 0 0" rpy="0 0 0"/>
      <geometry>
        <cylinder radius="0.0125" length="0.0125"/>
      </geometry>
    </collision>
  </link>

  <joint name="laser_joint" type="fixed">
    <origin xyz="0.036445 0 0.13" rpy="0 0 -1.57"/>
    <parent link="base_link"/>
    <child link="laser"/>
  </joint>

  <link name="camera_link">
    <inertial><origin xyz="0 0 0"/><mass value="0.001"/>
      <inertia ixx="1e-6" iyy="1e-6" izz="1e-6" ixy="0" ixz="0" iyz="0"/></inertial>
    <visual><geometry><box size="0.01 0.01 0.01"/></geometry></visual>
  </link>
  <joint name="camera_joint" type="fixed">
    <origin xyz="0.072916 0 0" rpy="0 0.17453 0"/>
    <parent link="base_link"/><child link="camera_link"/>
  </joint>
</robot>